<?xml version="1.0"?>
<robot name="manipulator" xmlns:xacro="http://ros.org/wiki/xacro">
 <material name="blue">
    <color rgba="0 0 0.8 1"/>
  </material>

  <material name="white">
    <color rgba="1 1 1 1"/>
  </material>


<link name="world"></link>

  <link name="base_link">
    <visual>
      <geometry>
        <cylinder length="0.5" radius="0.2"/>
      </geometry>
       <material name="blue"/>
       <origin rpy="0 0 0" xyz="0 0 0.25"/>
    </visual>
    <collision>
      <geometry>
        <cylinder length="0.5" radius="0.2"/>
      </geometry>
       <material name="blue"/>
       <origin rpy="0 0 0" xyz="0 0 0.25"/>
    </collision>
    <inertial>
      <mass value="1"/>
      <inertia
        ixx="0.0308" ixy="0.0" ixz="0.0"
        iyy="0.0308" iyz="0.0"
        izz="0.02"/>
    </inertial>
  </link>
  <xacro:macro name="hinge" params="name">
  <link name="${name}">
    <visual>
      <geometry>
        <sphere radius="0.25"/>
      </geometry>
       <material name="white"/>
    </visual>
    <collision>
      <geometry>
        <sphere radius="0.25"/>
      </geometry>
       <material name="white"/>
    </collision>
    <inertial>
      <mass value="0.2"/>
      <inertia
        ixx="0.0025" ixy="0.0" ixz="0.0"
        iyy="0.0025" iyz="0.0"
        izz="0.0025"/>
    </inertial>
  </link>
  </xacro:macro>
  <xacro:hinge name="first_spherical_joint"/>
  <xacro:hinge name="second_spherical_joint"/>
<link name="forearm">
    <visual>
      <geometry>
        <cylinder length="1" radius="0.2"/>
      </geometry>
      <material name="blue"/>
      <origin rpy="0 0 0" xyz="0 0 0.65"/>
    </visual>
    <collision>
      <geometry>
        <cylinder length="1" radius="0.2"/>
      </geometry>
       <material name="blue"/>
       <origin rpy="0 0 0" xyz="0 0 0.65"/>
    </collision>
    <inertial>
      <mass value="1"/>
      <inertia
        ixx="0.093" ixy="0.0" ixz="0.0"
        iyy="0.093" iyz="0.0"
        izz="0.02"/>
    </inertial>
  </link>

  <link name="arm">
    <visual>
      <geometry>
        <cylinder length="1" radius="0.2"/>
      </geometry>
      <material name="blue"/>
      <origin rpy="0 0 0" xyz="0 0 0.65"/>
    </visual>
    <collision>
      <geometry>
        <cylinder length="1" radius="0.2"/>
      </geometry>
       <material name="blue"/>
       <origin rpy="0 0 0" xyz="0 0 0.65"/>
    </collision>
    <inertial>
      <mass value="1"/>
      <inertia
        ixx="0.093" ixy="0.0" ixz="0.0"
        iyy="0.093" iyz="0.0"
        izz="0.00"/>
    </inertial>
  </link>

<xacro:macro name="gripper" params="type position height lower upper">
  <link name="gripper_${type}">
    <visual>
      <geometry>
        <cylinder length="0.2" radius="0.01"/>
      </geometry>
      <material name="white"/>
      <origin rpy="0 0 0" xyz="0 ${position} ${height}"/>
    </visual>
    <collision>
      <geometry>
        <cylinder length="0.2" radius="0.01"/>
      </geometry>
       <material name="white"/>
       <origin rpy="0 0 0" xyz="0 ${position} ${height}"/>
    </collision>
    <inertial>
      <mass value="0.01"/>
      <inertia
        ixx="0.00003358" ixy="0.0" ixz="0.0"
        iyy="0.00003358" iyz="0.0"
        izz="0.0000005"/>
    </inertial>
  </link>
  <joint name="arm_to_${type}_gripper" type="revolute">
    <parent link="arm"/>
    <child link="gripper_${type}"/>
    <origin xyz="0 ${position} 1.15"/>
    <axis xyz="1 0 0"/>
    <limit effort="1000.0" lower="${lower}" upper="${upper}" velocity="0.5"/>
    <dynamics damping="50" friction="1"/>
  </joint>
</xacro:macro>
<xacro:gripper type="left" position="0.05" height="0.05" lower="0.0" upper="0.48"/>
<xacro:gripper type="right" position="-0.05" height="0.05" lower="-0.48" upper="0.0"/>


<joint name="world_to_base_link" type="fixed">
     <parent link="world"/>
     <child link="base_link"/>
     <origin xyz="0 0 -1"/>
     <dynamics damping="50" friction="1"/>
</joint>

  <joint name="base_to_first_spherical_joint" type="continuous">
    <parent link="base_link"/>
    <child link="first_spherical_joint"/>
    <origin xyz="0 0 0.65"/>
    <axis xyz="1 0 0"/>
    <dynamics damping="50" friction="1"/>
  </joint>

  <joint name="first_spherical_joint_to_forearm" type="continuous">
    <parent link="first_spherical_joint"/>
    <child link="forearm"/>
    <origin xyz="0 0 0"/>
    <axis xyz="0 1 0"/>
    <dynamics damping="50" friction="1"/>
  </joint>

   <joint name="forearm_to_second_spherical_joint" type="continuous">
    <parent link="forearm"/>
    <child link="second_spherical_joint"/>
    <origin xyz="0 0 1.3"/>
    <axis xyz="0 1 0"/>
    <dynamics damping="50" friction="1"/>
  </joint>

     <joint name="second_spherical_joint_to_arm" type="continuous">
    <parent link="second_spherical_joint"/>
    <child link="arm"/>
    <origin xyz="0 0 0"/>
    <axis xyz="1 0 0"/>
    <dynamics damping="50" friction="1"/>
  </joint>



  <gazebo reference="base_link">
       <material>Gazebo/Blue</material>
       <turnGravityOff>true</turnGravityOff>
  </gazebo>
  <gazebo reference="first_spherical_joint">
       <material>Gazebo/White</material>
       <turnGravityOff>true</turnGravityOff>
  </gazebo>
<gazebo reference="forearm">
       <material>Gazebo/Blue</material>
       <turnGravityOff>true</turnGravityOff>
  </gazebo>
  <gazebo reference="second_spherical_joint">
       <material>Gazebo/White</material>
       <turnGravityOff>true</turnGravityOff>
  </gazebo>
  <gazebo reference="arm">
       <material>Gazebo/Blue</material>
       <turnGravityOff>true</turnGravityOff>
  </gazebo>
</robot>